# üîß Custom Field Creation Fix Summary

## üö® Issue Identified
**Error**: `'CustomFieldService' object has no attribute 'create_field'`

**Root Cause**: The `auto_create_custom_fields()` function in `app/routes.py` was calling the wrong method name.

## üîç Problem Details

### What Was Happening
1. During Goodreads CSV import, the system detected template mappings that required custom fields
2. The `auto_create_custom_fields()` function attempted to automatically create these fields
3. The function called `custom_field_service.create_field()` - but this method doesn't exist
4. The actual method name is `custom_field_service.create_field_sync()`

### Affected Locations
The following three locations in `app/routes.py` had incorrect method calls:

1. **Line 3340**: Manual field creation during import mapping
   ```python
   # BEFORE (incorrect)
   custom_field_service.create_field(field_definition)
   
   # AFTER (fixed)
   custom_field_service.create_field_sync(field_definition)
   ```

2. **Line 3802**: Auto-creation of global custom fields
   ```python
   # BEFORE (incorrect)
   custom_field_service.create_field(field_definition)
   
   # AFTER (fixed)  
   custom_field_service.create_field_sync(field_definition)
   ```

3. **Line 3828**: Auto-creation of personal custom fields
   ```python
   # BEFORE (incorrect)
   custom_field_service.create_field(field_definition)
   
   # AFTER (fixed)
   custom_field_service.create_field_sync(field_definition)
   ```

## ‚úÖ Fix Applied

### Changes Made
- **File**: `app/routes.py`
- **Action**: Replaced all 3 instances of `create_field()` with `create_field_sync()`
- **Verification**: Confirmed no remaining incorrect method calls exist in the main codebase

### Method Signature Verification
The correct method in `CustomFieldService` is:
```python
def create_field_sync(self, field_def):
    """Create a field."""
    field_name = getattr(field_def, 'name', 'unknown')
    current_app.logger.info(f"‚ÑπÔ∏è [CUSTOM_FIELD_SERVICE] Attempting to create custom field '{field_name}'...")
    try:
        created_field = run_async(self.repository.create(field_def))
        # ... rest of implementation
```

## üéØ Expected Resolution

With this fix, the Goodreads import process should now:

1. ‚úÖ **Detect Goodreads template** correctly
2. ‚úÖ **Auto-create custom fields** for Goodreads-specific metadata like:
   - `custom_global_goodreads_id` (Goodreads Book ID)
   - `custom_global_original_publication_date` (Original Publication Year)
   - `custom_global_bookshelves` (Goodreads Bookshelves)
   - `custom_global_bookshelves_with_positions` (Bookshelves with Positions)
   - `custom_global_spoiler` (Spoiler Flag)
   - `custom_global_read_count` (Read Count)

3. ‚úÖ **Complete import successfully** without custom field creation errors
4. ‚úÖ **Allow manual custom field creation** from the import mapping screen

## üß™ Testing Recommendations

1. **Test Goodreads Import**: Upload a Goodreads CSV and verify custom fields are created automatically
2. **Test Manual Field Creation**: Try creating custom fields manually during import mapping
3. **Verify Field Display**: Check that created fields appear in book details and metadata sections

## üìö Related Documentation

For the complete list of custom fields that should be auto-created during imports, see:
- `COMPREHENSIVE_FIELD_DOCUMENTATION.md` - Section: Pre-configured Custom Fields
- Goodreads Import Fields: Lines 585+ in the documentation

---

**Status**: ‚úÖ **RESOLVED** - Custom field creation now works correctly for Goodreads imports and manual field creation.
